Workbook

Sheet Daily Rollup
B2: GOOD MORNING!!! — Today's Call Delivery Strategy
B3: ALL TIMES EASTERN. Changes are communicated through the day — reach your Point of Contact via the Teams channel or email Call Delivery Systems.
B5: Strategy Date: | C5: 46220 | E5: Auto-Messaging Voice: | G5: =IFERROR(INDEX('Ref Voice'!$B$2:$B$40,MATCH($C$5,'Ref Voice'!$A$2:$A$40,0)),"") -> Female | I5: Yellow cells are yours: set the date (or type =TODAY() for live use) and the voice for the day.
B7: Business Group | C7: Passes | D7: 0.33333333 | E7: 0.375 | F7: 0.41666667 | G7: 0.45833333 | H7: 0.5 | I7: 0.54166667 | J7: 0.58333333 | K7: 0.625 | L7: 0.66666667 | M7: 0.70833333 | N7: 0.75 | O7: 0.79166667 | P7: 0.83333333 | Q7: 0.875 | R7: Special Instructions
B8: FE | C8: =COUNTIFS(Consolidated!$B$5:$B$659,$B8,Consolidated!$C$5:$C$659,$C$5) -> 6 | D8: =IFERROR(INDEX(RollupData!$B$2:$B$656,MATCH($B8&"|"&TEXT($C$5,"yyyymmdd")&"|"&8,RollupData!$A$2:$A$656,0)),"") -> 8:30a E AMs | E8: =IFERROR(INDEX(RollupData!$B$2:$B$656,MATCH($B8&"|"&TEXT($C$5,"yyyymmdd")&"|"&9,RollupData!$A$2:$A$656,0)),"") | F8: =IFERROR(INDEX(RollupData!$B$2:$B$656,MATCH($B8&"|"&TEXT($C$5,"yyyymmdd")&"|"&10,RollupData!$A$2:$A$656,0)),"") | G8: =IFERROR(INDEX(RollupData!$B$2:$B$656,MATCH($B8&"|"&TEXT($C$5,"yyyymmdd")&"|"&11,RollupData!$A$2:$A$656,0)),"") -> 11:00a C-M-P AMs | H8: =IFERROR(INDEX(RollupData!$B$2:$B$656,MATCH($B8&"|"&TEXT($C$5,"yyyymmdd")&"|"&12,RollupData!$A$2:$A$656,0)),"") -> 12:30p Branch | I8: =IFERROR(INDEX(RollupData!$B$2:$B$656,MATCH($B8&"|"&TEXT($C$5,"yyyymmdd")&"|"&13,RollupData!$A$2:$A$656,0)),"") -> 1:30p WFO | J8: =IFERROR(INDEX(RollupData!$B$2:$B$656,MATCH($B8&"|"&TEXT($C$5,"yyyymmdd")&"|"&14,RollupData!$A$2:$A$656,0)),"") | K8: =IFERROR(INDEX(RollupData!$B$2:$B$656,MATCH($B8&"|"&TEXT($C$5,"yyyymmdd")&"|"&15,RollupData!$A$2:$A$656,0)),"") | L8: =IFERROR(INDEX(RollupData!$B$2:$B$656,MATCH($B8&"|"&TEXT($C$5,"yyyymmdd")&"|"&16,RollupData!$A$2:$A$656,0)),"") | M8: =IFERROR(INDEX(RollupData!$B$2:$B$656,MATCH($B8&"|"&TEXT($C$5,"yyyymmdd")&"|"&17,RollupData!$A$2:$A$656,0)),"") -> 5:00p Blitz | N8: =IFERROR(INDEX(RollupData!$B$2:$B$656,MATCH($B8&"|"&TEXT($C$5,"yyyymmdd")&"|"&18,RollupData!$A$2:$A$656,0)),"") | O8: =IFERROR(INDEX(RollupData!$B$2:$B$656,MATCH($B8&"|"&TEXT($C$5,"yyyymmdd")&"|"&19,RollupData!$A$2:$A$656,0)),"") | P8: =IFERROR(INDEX(RollupData!$B$2:$B$656,MATCH($B8&"|"&TEXT($C$5,"yyyymmdd")&"|"&20,RollupData!$A$2:$A$656,0)),"") -> 8:00p TSC (All) | Q8: =IFERROR(INDEX(RollupData!$B$2:$B$656,MATCH($B8&"|"&TEXT($C$5,"yyyymmdd")&"|"&21,RollupData!$A$2:$A$656,0)),"") | R8: =IFERROR(INDEX(RollupData!$D$2:$D$656,MATCH($B8&"|"&TEXT($C$5,"yyyymmdd"),RollupData!$C$2:$C$656,0)),"")
B9: BE | C9: =COUNTIFS(Consolidated!$B$5:$B$659,$B9,Consolidated!$C$5:$C$659,$C$5) -> 5 | D9: =IFERROR(INDEX(RollupData!$B$2:$B$656,MATCH($B9&"|"&TEXT($C$5,"yyyymmdd")&"|"&8,RollupData!$A$2:$A$656,0)),"") -> 8:30a E AMs | E9: =IFERROR(INDEX(RollupData!$B$2:$B$656,MATCH($B9&"|"&TEXT($C$5,"yyyymmdd")&"|"&9,RollupData!$A$2:$A$656,0)),"") | F9: =IFERROR(INDEX(RollupData!$B$2:$B$656,MATCH($B9&"|"&TEXT($C$5,"yyyymmdd")&"|"&10,RollupData!$A$2:$A$656,0)),"") | G9: =IFERROR(INDEX(RollupData!$B$2:$B$656,MATCH($B9&"|"&TEXT($C$5,"yyyymmdd")&"|"&11,RollupData!$A$2:$A$656,0)),"") -> 11:00a C-M-P AMs | H9: =IFERROR(INDEX(RollupData!$B$2:$B$656,MATCH($B9&"|"&TEXT($C$5,"yyyymmdd")&"|"&12,RollupData!$A$2:$A$656,0)),"") | I9: =IFERROR(INDEX(RollupData!$B$2:$B$656,MATCH($B9&"|"&TEXT($C$5,"yyyymmdd")&"|"&13,RollupData!$A$2:$A$656,0)),"") -> 1:00p WFO | J9: =IFERROR(INDEX(RollupData!$B$2:$B$656,MATCH($B9&"|"&TEXT($C$5,"yyyymmdd")&"|"&14,RollupData!$A$2:$A$656,0)),"") | K9: =IFERROR(INDEX(RollupData!$B$2:$B$656,MATCH($B9&"|"&TEXT($C$5,"yyyymmdd")&"|"&15,RollupData!$A$2:$A$656,0)),"") | L9: =IFERROR(INDEX(RollupData!$B$2:$B$656,MATCH($B9&"|"&TEXT($C$5,"yyyymmdd")&"|"&16,RollupData!$A$2:$A$656,0)),"") | M9: =IFERROR(INDEX(RollupData!$B$2:$B$656,MATCH($B9&"|"&TEXT($C$5,"yyyymmdd")&"|"&17,RollupData!$A$2:$A$656,0)),"") -> 5:00p Blitz | N9: =IFERROR(INDEX(RollupData!$B$2:$B$656,MATCH($B9&"|"&TEXT($C$5,"yyyymmdd")&"|"&18,RollupData!$A$2:$A$656,0)),"") | O9: =IFERROR(INDEX(RollupData!$B$2:$B$656,MATCH($B9&"|"&TEXT($C$5,"yyyymmdd")&"|"&19,RollupData!$A$2:$A$656,0)),"") | P9: =IFERROR(INDEX(RollupData!$B$2:$B$656,MATCH($B9&"|"&TEXT($C$5,"yyyymmdd")&"|"&20,RollupData!$A$2:$A$656,0)),"") -> 8:00p TSC (All) | Q9: =IFERROR(INDEX(RollupData!$B$2:$B$656,MATCH($B9&"|"&TEXT($C$5,"yyyymmdd")&"|"&21,RollupData!$A$2:$A$656,0)),"") | R9: =IFERROR(INDEX(RollupData!$D$2:$D$656,MATCH($B9&"|"&TEXT($C$5,"yyyymmdd"),RollupData!$C$2:$C$656,0)),"")
B10: PCO | C10: =COUNTIFS(Consolidated!$B$5:$B$659,$B10,Consolidated!$C$5:$C$659,$C$5) -> 5 | D10: =IFERROR(INDEX(RollupData!$B$2:$B$656,MATCH($B10&"|"&TEXT($C$5,"yyyymmdd")&"|"&8,RollupData!$A$2:$A$656,0)),"") | E10: =IFERROR(INDEX(RollupData!$B$2:$B$656,MATCH($B10&"|"&TEXT($C$5,"yyyymmdd")&"|"&9,RollupData!$A$2:$A$656,0)),"") -> 9:00a E-C AMs | F10: =IFERROR(INDEX(RollupData!$B$2:$B$656,MATCH($B10&"|"&TEXT($C$5,"yyyymmdd")&"|"&10,RollupData!$A$2:$A$656,0)),"") | G10: =IFERROR(INDEX(RollupData!$B$2:$B$656,MATCH($B10&"|"&TEXT($C$5,"yyyymmdd")&"|"&11,RollupData!$A$2:$A$656,0)),"") -> 11:15a M-P AMs | H10: =IFERROR(INDEX(RollupData!$B$2:$B$656,MATCH($B10&"|"&TEXT($C$5,"yyyymmdd")&"|"&12,RollupData!$A$2:$A$656,0)),"") | I10: =IFERROR(INDEX(RollupData!$B$2:$B$656,MATCH($B10&"|"&TEXT($C$5,"yyyymmdd")&"|"&13,RollupData!$A$2:$A$656,0)),"") -> 1:00p WFO | J10: =IFERROR(INDEX(RollupData!$B$2:$B$656,MATCH($B10&"|"&TEXT($C$5,"yyyymmdd")&"|"&14,RollupData!$A$2:$A$656,0)),"") | K10: =IFERROR(INDEX(RollupData!$B$2:$B$656,MATCH($B10&"|"&TEXT($C$5,"yyyymmdd")&"|"&15,RollupData!$A$2:$A$656,0)),"") | L10: =IFERROR(INDEX(RollupData!$B$2:$B$656,MATCH($B10&"|"&TEXT($C$5,"yyyymmdd")&"|"&16,RollupData!$A$2:$A$656,0)),"") | M10: =IFERROR(INDEX(RollupData!$B$2:$B$656,MATCH($B10&"|"&TEXT($C$5,"yyyymmdd")&"|"&17,RollupData!$A$2:$A$656,0)),"") -> 5:00p Blitz | N10: =IFERROR(INDEX(RollupData!$B$2:$B$656,MATCH($B10&"|"&TEXT($C$5,"yyyymmdd")&"|"&18,RollupData!$A$2:$A$656,0)),"") | O10: =IFERROR(INDEX(RollupData!$B$2:$B$656,MATCH($B10&"|"&TEXT($C$5,"yyyymmdd")&"|"&19,RollupData!$A$2:$A$656,0)),"") | P10: =IFERROR(INDEX(RollupData!$B$2:$B$656,MATCH($B10&"|"&TEXT($C$5,"yyyymmdd")&"|"&20,RollupData!$A$2:$A$656,0)),"") -> 8:00p TSC (All) | Q10: =IFERROR(INDEX(RollupData!$B$2:$B$656,MATCH($B10&"|"&TEXT($C$5,"yyyymmdd")&"|"&21,RollupData!$A$2:$A$656,0)),"") | R10: =IFERROR(INDEX(RollupData!$D$2:$D$656,MATCH($B10&"|"&TEXT($C$5,"yyyymmdd"),RollupData!$C$2:$C$656,0)),"")
B11: Auto | C11: =COUNTIFS(Consolidated!$B$5:$B$659,$B11,Consolidated!$C$5:$C$659,$C$5) -> 5 | D11: =IFERROR(INDEX(RollupData!$B$2:$B$656,MATCH($B11&"|"&TEXT($C$5,"yyyymmdd")&"|"&8,RollupData!$A$2:$A$656,0)),"") -> 8:15a E AMs | E11: =IFERROR(INDEX(RollupData!$B$2:$B$656,MATCH($B11&"|"&TEXT($C$5,"yyyymmdd")&"|"&9,RollupData!$A$2:$A$656,0)),"") | F11: =IFERROR(INDEX(RollupData!$B$2:$B$656,MATCH($B11&"|"&TEXT($C$5,"yyyymmdd")&"|"&10,RollupData!$A$2:$A$656,0)),"") | G11: =IFERROR(INDEX(RollupData!$B$2:$B$656,MATCH($B11&"|"&TEXT($C$5,"yyyymmdd")&"|"&11,RollupData!$A$2:$A$656,0)),"") -> 11:30a C-M-P AMs | H11: =IFERROR(INDEX(RollupData!$B$2:$B$656,MATCH($B11&"|"&TEXT($C$5,"yyyymmdd")&"|"&12,RollupData!$A$2:$A$656,0)),"") | I11: =IFERROR(INDEX(RollupData!$B$2:$B$656,MATCH($B11&"|"&TEXT($C$5,"yyyymmdd")&"|"&13,RollupData!$A$2:$A$656,0)),"") -> 1:30p WFO | J11: =IFERROR(INDEX(RollupData!$B$2:$B$656,MATCH($B11&"|"&TEXT($C$5,"yyyymmdd")&"|"&14,RollupData!$A$2:$A$656,0)),"") | K11: =IFERROR(INDEX(RollupData!$B$2:$B$656,MATCH($B11&"|"&TEXT($C$5,"yyyymmdd")&"|"&15,RollupData!$A$2:$A$656,0)),"") | L11: =IFERROR(INDEX(RollupData!$B$2:$B$656,MATCH($B11&"|"&TEXT($C$5,"yyyymmdd")&"|"&16,RollupData!$A$2:$A$656,0)),"") | M11: =IFERROR(INDEX(RollupData!$B$2:$B$656,MATCH($B11&"|"&TEXT($C$5,"yyyymmdd")&"|"&17,RollupData!$A$2:$A$656,0)),"") -> 5:00p Blitz | N11: =IFERROR(INDEX(RollupData!$B$2:$B$656,MATCH($B11&"|"&TEXT($C$5,"yyyymmdd")&"|"&18,RollupData!$A$2:$A$656,0)),"") | O11: =IFERROR(INDEX(RollupData!$B$2:$B$656,MATCH($B11&"|"&TEXT($C$5,"yyyymmdd")&"|"&19,RollupData!$A$2:$A$656,0)),"") | P11: =IFERROR(INDEX(RollupData!$B$2:$B$656,MATCH($B11&"|"&TEXT($C$5,"yyyymmdd")&"|"&20,RollupData!$A$2:$A$656,0)),"") -> 8:00p TSC (All) | Q11: =IFERROR(INDEX(RollupData!$B$2:$B$656,MATCH($B11&"|"&TEXT($C$5,"yyyymmdd")&"|"&21,RollupData!$A$2:$A$656,0)),"") | R11: =IFERROR(INDEX(RollupData!$D$2:$D$656,MATCH($B11&"|"&TEXT($C$5,"yyyymmdd"),RollupData!$C$2:$C$656,0)),"") -> Slowpay AM Daily
B12: Repo | C12: =COUNTIFS(Consolidated!$B$5:$B$659,$B12,Consolidated!$C$5:$C$659,$C$5) -> 4 | D12: =IFERROR(INDEX(RollupData!$B$2:$B$656,MATCH($B12&"|"&TEXT($C$5,"yyyymmdd")&"|"&8,RollupData!$A$2:$A$656,0)),"") -> 8:15a Repo | E12: =IFERROR(INDEX(RollupData!$B$2:$B$656,MATCH($B12&"|"&TEXT($C$5,"yyyymmdd")&"|"&9,RollupData!$A$2:$A$656,0)),"") | F12: =IFERROR(INDEX(RollupData!$B$2:$B$656,MATCH($B12&"|"&TEXT($C$5,"yyyymmdd")&"|"&10,RollupData!$A$2:$A$656,0)),"") -> 10:00a Repo | G12: =IFERROR(INDEX(RollupData!$B$2:$B$656,MATCH($B12&"|"&TEXT($C$5,"yyyymmdd")&"|"&11,RollupData!$A$2:$A$656,0)),"") | H12: =IFERROR(INDEX(RollupData!$B$2:$B$656,MATCH($B12&"|"&TEXT($C$5,"yyyymmdd")&"|"&12,RollupData!$A$2:$A$656,0)),"") | I12: =IFERROR(INDEX(RollupData!$B$2:$B$656,MATCH($B12&"|"&TEXT($C$5,"yyyymmdd")&"|"&13,RollupData!$A$2:$A$656,0)),"") -> 1:00p RP | J12: =IFERROR(INDEX(RollupData!$B$2:$B$656,MATCH($B12&"|"&TEXT($C$5,"yyyymmdd")&"|"&14,RollupData!$A$2:$A$656,0)),"") -> 2:00p Repo | K12: =IFERROR(INDEX(RollupData!$B$2:$B$656,MATCH($B12&"|"&TEXT($C$5,"yyyymmdd")&"|"&15,RollupData!$A$2:$A$656,0)),"") | L12: =IFERROR(INDEX(RollupData!$B$2:$B$656,MATCH($B12&"|"&TEXT($C$5,"yyyymmdd")&"|"&16,RollupData!$A$2:$A$656,0)),"") | M12: =IFERROR(INDEX(RollupData!$B$2:$B$656,MATCH($B12&"|"&TEXT($C$5,"yyyymmdd")&"|"&17,RollupData!$A$2:$A$656,0)),"") | N12: =IFERROR(INDEX(RollupData!$B$2:$B$656,MATCH($B12&"|"&TEXT($C$5,"yyyymmdd")&"|"&18,RollupData!$A$2:$A$656,0)),"") | O12: =IFERROR(INDEX(RollupData!$B$2:$B$656,MATCH($B12&"|"&TEXT($C$5,"yyyymmdd")&"|"&19,RollupData!$A$2:$A$656,0)),"") | P12: =IFERROR(INDEX(RollupData!$B$2:$B$656,MATCH($B12&"|"&TEXT($C$5,"yyyymmdd")&"|"&20,RollupData!$A$2:$A$656,0)),"") | Q12: =IFERROR(INDEX(RollupData!$B$2:$B$656,MATCH($B12&"|"&TEXT($C$5,"yyyymmdd")&"|"&21,RollupData!$A$2:$A$656,0)),"") | R12: =IFERROR(INDEX(RollupData!$D$2:$D$656,MATCH($B12&"|"&TEXT($C$5,"yyyymmdd"),RollupData!$C$2:$C$656,0)),"") -> AM Daily
B13: MOD | C13: =COUNTIFS(Consolidated!$B$5:$B$659,$B13,Consolidated!$C$5:$C$659,$C$5) -> 0 | D13: =IFERROR(INDEX(RollupData!$B$2:$B$656,MATCH($B13&"|"&TEXT($C$5,"yyyymmdd")&"|"&8,RollupData!$A$2:$A$656,0)),"") | E13: =IFERROR(INDEX(RollupData!$B$2:$B$656,MATCH($B13&"|"&TEXT($C$5,"yyyymmdd")&"|"&9,RollupData!$A$2:$A$656,0)),"") | F13: =IFERROR(INDEX(RollupData!$B$2:$B$656,MATCH($B13&"|"&TEXT($C$5,"yyyymmdd")&"|"&10,RollupData!$A$2:$A$656,0)),"") | G13: =IFERROR(INDEX(RollupData!$B$2:$B$656,MATCH($B13&"|"&TEXT($C$5,"yyyymmdd")&"|"&11,RollupData!$A$2:$A$656,0)),"") | H13: =IFERROR(INDEX(RollupData!$B$2:$B$656,MATCH($B13&"|"&TEXT($C$5,"yyyymmdd")&"|"&12,RollupData!$A$2:$A$656,0)),"") | I13: =IFERROR(INDEX(RollupData!$B$2:$B$656,MATCH($B13&"|"&TEXT($C$5,"yyyymmdd")&"|"&13,RollupData!$A$2:$A$656,0)),"") | J13: =IFERROR(INDEX(RollupData!$B$2:$B$656,MATCH($B13&"|"&TEXT($C$5,"yyyymmdd")&"|"&14,RollupData!$A$2:$A$656,0)),"") | K13: =IFERROR(INDEX(RollupData!$B$2:$B$656,MATCH($B13&"|"&TEXT($C$5,"yyyymmdd")&"|"&15,RollupData!$A$2:$A$656,0)),"") | L13: =IFERROR(INDEX(RollupData!$B$2:$B$656,MATCH($B13&"|"&TEXT($C$5,"yyyymmdd")&"|"&16,RollupData!$A$2:$A$656,0)),"") | M13: =IFERROR(INDEX(RollupData!$B$2:$B$656,MATCH($B13&"|"&TEXT($C$5,"yyyymmdd")&"|"&17,RollupData!$A$2:$A$656,0)),"") | N13: =IFERROR(INDEX(RollupData!$B$2:$B$656,MATCH($B13&"|"&TEXT($C$5,"yyyymmdd")&"|"&18,RollupData!$A$2:$A$656,0)),"") | O13: =IFERROR(INDEX(RollupData!$B$2:$B$656,MATCH($B13&"|"&TEXT($C$5,"yyyymmdd")&"|"&19,RollupData!$A$2:$A$656,0)),"") | P13: =IFERROR(INDEX(RollupData!$B$2:$B$656,MATCH($B13&"|"&TEXT($C$5,"yyyymmdd")&"|"&20,RollupData!$A$2:$A$656,0)),"") | Q13: =IFERROR(INDEX(RollupData!$B$2:$B$656,MATCH($B13&"|"&TEXT($C$5,"yyyymmdd")&"|"&21,RollupData!$A$2:$A$656,0)),"") | R13: =IFERROR(INDEX(RollupData!$D$2:$D$656,MATCH($B13&"|"&TEXT($C$5,"yyyymmdd"),RollupData!$C$2:$C$656,0)),"")
B14: Branch Central | C14: =COUNTIFS(Consolidated!$B$5:$B$659,$B14,Consolidated!$C$5:$C$659,$C$5) -> 1 | D14: =IFERROR(INDEX(RollupData!$B$2:$B$656,MATCH($B14&"|"&TEXT($C$5,"yyyymmdd")&"|"&8,RollupData!$A$2:$A$656,0)),"") | E14: =IFERROR(INDEX(RollupData!$B$2:$B$656,MATCH($B14&"|"&TEXT($C$5,"yyyymmdd")&"|"&9,RollupData!$A$2:$A$656,0)),"") | F14: =IFERROR(INDEX(RollupData!$B$2:$B$656,MATCH($B14&"|"&TEXT($C$5,"yyyymmdd")&"|"&10,RollupData!$A$2:$A$656,0)),"") | G14: =IFERROR(INDEX(RollupData!$B$2:$B$656,MATCH($B14&"|"&TEXT($C$5,"yyyymmdd")&"|"&11,RollupData!$A$2:$A$656,0)),"") | H14: =IFERROR(INDEX(RollupData!$B$2:$B$656,MATCH($B14&"|"&TEXT($C$5,"yyyymmdd")&"|"&12,RollupData!$A$2:$A$656,0)),"") -> 12:30p E-C 1s & Slow | I14: =IFERROR(INDEX(RollupData!$B$2:$B$656,MATCH($B14&"|"&TEXT($C$5,"yyyymmdd")&"|"&13,RollupData!$A$2:$A$656,0)),"") | J14: =IFERROR(INDEX(RollupData!$B$2:$B$656,MATCH($B14&"|"&TEXT($C$5,"yyyymmdd")&"|"&14,RollupData!$A$2:$A$656,0)),"") | K14: =IFERROR(INDEX(RollupData!$B$2:$B$656,MATCH($B14&"|"&TEXT($C$5,"yyyymmdd")&"|"&15,RollupData!$A$2:$A$656,0)),"") | L14: =IFERROR(INDEX(RollupData!$B$2:$B$656,MATCH($B14&"|"&TEXT($C$5,"yyyymmdd")&"|"&16,RollupData!$A$2:$A$656,0)),"") | M14: =IFERROR(INDEX(RollupData!$B$2:$B$656,MATCH($B14&"|"&TEXT($C$5,"yyyymmdd")&"|"&17,RollupData!$A$2:$A$656,0)),"") | N14: =IFERROR(INDEX(RollupData!$B$2:$B$656,MATCH($B14&"|"&TEXT($C$5,"yyyymmdd")&"|"&18,RollupData!$A$2:$A$656,0)),"") | O14: =IFERROR(INDEX(RollupData!$B$2:$B$656,MATCH($B14&"|"&TEXT($C$5,"yyyymmdd")&"|"&19,RollupData!$A$2:$A$656,0)),"") | P14: =IFERROR(INDEX(RollupData!$B$2:$B$656,MATCH($B14&"|"&TEXT($C$5,"yyyymmdd")&"|"&20,RollupData!$A$2:$A$656,0)),"") | Q14: =IFERROR(INDEX(RollupData!$B$2:$B$656,MATCH($B14&"|"&TEXT($C$5,"yyyymmdd")&"|"&21,RollupData!$A$2:$A$656,0)),"") | R14: =IFERROR(INDEX(RollupData!$D$2:$D$656,MATCH($B14&"|"&TEXT($C$5,"yyyymmdd"),RollupData!$C$2:$C$656,0)),"")
B15: Branch Vendor | C15: =COUNTIFS(Consolidated!$B$5:$B$659,$B15,Consolidated!$C$5:$C$659,$C$5) -> 1 | D15: =IFERROR(INDEX(RollupData!$B$2:$B$656,MATCH($B15&"|"&TEXT($C$5,"yyyymmdd")&"|"&8,RollupData!$A$2:$A$656,0)),"") | E15: =IFERROR(INDEX(RollupData!$B$2:$B$656,MATCH($B15&"|"&TEXT($C$5,"yyyymmdd")&"|"&9,RollupData!$A$2:$A$656,0)),"") | F15: =IFERROR(INDEX(RollupData!$B$2:$B$656,MATCH($B15&"|"&TEXT($C$5,"yyyymmdd")&"|"&10,RollupData!$A$2:$A$656,0)),"") | G15: =IFERROR(INDEX(RollupData!$B$2:$B$656,MATCH($B15&"|"&TEXT($C$5,"yyyymmdd")&"|"&11,RollupData!$A$2:$A$656,0)),"") | H15: =IFERROR(INDEX(RollupData!$B$2:$B$656,MATCH($B15&"|"&TEXT($C$5,"yyyymmdd")&"|"&12,RollupData!$A$2:$A$656,0)),"") | I15: =IFERROR(INDEX(RollupData!$B$2:$B$656,MATCH($B15&"|"&TEXT($C$5,"yyyymmdd")&"|"&13,RollupData!$A$2:$A$656,0)),"") | J15: =IFERROR(INDEX(RollupData!$B$2:$B$656,MATCH($B15&"|"&TEXT($C$5,"yyyymmdd")&"|"&14,RollupData!$A$2:$A$656,0)),"") | K15: =IFERROR(INDEX(RollupData!$B$2:$B$656,MATCH($B15&"|"&TEXT($C$5,"yyyymmdd")&"|"&15,RollupData!$A$2:$A$656,0)),"") | L15: =IFERROR(INDEX(RollupData!$B$2:$B$656,MATCH($B15&"|"&TEXT($C$5,"yyyymmdd")&"|"&16,RollupData!$A$2:$A$656,0)),"") | M15: =IFERROR(INDEX(RollupData!$B$2:$B$656,MATCH($B15&"|"&TEXT($C$5,"yyyymmdd")&"|"&17,RollupData!$A$2:$A$656,0)),"") | N15: =IFERROR(INDEX(RollupData!$B$2:$B$656,MATCH($B15&"|"&TEXT($C$5,"yyyymmdd")&"|"&18,RollupData!$A$2:$A$656,0)),"") -> 6:00p Vendor | O15: =IFERROR(INDEX(RollupData!$B$2:$B$656,MATCH($B15&"|"&TEXT($C$5,"yyyymmdd")&"|"&19,RollupData!$A$2:$A$656,0)),"") | P15: =IFERROR(INDEX(RollupData!$B$2:$B$656,MATCH($B15&"|"&TEXT($C$5,"yyyymmdd")&"|"&20,RollupData!$A$2:$A$656,0)),"") | Q15: =IFERROR(INDEX(RollupData!$B$2:$B$656,MATCH($B15&"|"&TEXT($C$5,"yyyymmdd")&"|"&21,RollupData!$A$2:$A$656,0)),"") | R15: =IFERROR(INDEX(RollupData!$D$2:$D$656,MATCH($B15&"|"&TEXT($C$5,"yyyymmdd"),RollupData!$C$2:$C$656,0)),"")
B16: Card | C16: =COUNTIFS(Consolidated!$B$5:$B$659,$B16,Consolidated!$C$5:$C$659,$C$5) -> 5 | D16: =IFERROR(INDEX(RollupData!$B$2:$B$656,MATCH($B16&"|"&TEXT($C$5,"yyyymmdd")&"|"&8,RollupData!$A$2:$A$656,0)),"") -> 8:00a | E16: =IFERROR(INDEX(RollupData!$B$2:$B$656,MATCH($B16&"|"&TEXT($C$5,"yyyymmdd")&"|"&9,RollupData!$A$2:$A$656,0)),"") | F16: =IFERROR(INDEX(RollupData!$B$2:$B$656,MATCH($B16&"|"&TEXT($C$5,"yyyymmdd")&"|"&10,RollupData!$A$2:$A$656,0)),"") | G16: =IFERROR(INDEX(RollupData!$B$2:$B$656,MATCH($B16&"|"&TEXT($C$5,"yyyymmdd")&"|"&11,RollupData!$A$2:$A$656,0)),"") | H16: =IFERROR(INDEX(RollupData!$B$2:$B$656,MATCH($B16&"|"&TEXT($C$5,"yyyymmdd")&"|"&12,RollupData!$A$2:$A$656,0)),"") -> 12:00p | I16: =IFERROR(INDEX(RollupData!$B$2:$B$656,MATCH($B16&"|"&TEXT($C$5,"yyyymmdd")&"|"&13,RollupData!$A$2:$A$656,0)),"") | J16: =IFERROR(INDEX(RollupData!$B$2:$B$656,MATCH($B16&"|"&TEXT($C$5,"yyyymmdd")&"|"&14,RollupData!$A$2:$A$656,0)),"") -> 2:00p ASAP | K16: =IFERROR(INDEX(RollupData!$B$2:$B$656,MATCH($B16&"|"&TEXT($C$5,"yyyymmdd")&"|"&15,RollupData!$A$2:$A$656,0)),"") | L16: =IFERROR(INDEX(RollupData!$B$2:$B$656,MATCH($B16&"|"&TEXT($C$5,"yyyymmdd")&"|"&16,RollupData!$A$2:$A$656,0)),"") -> 4:00p ASAP | M16: =IFERROR(INDEX(RollupData!$B$2:$B$656,MATCH($B16&"|"&TEXT($C$5,"yyyymmdd")&"|"&17,RollupData!$A$2:$A$656,0)),"") | N16: =IFERROR(INDEX(RollupData!$B$2:$B$656,MATCH($B16&"|"&TEXT($C$5,"yyyymmdd")&"|"&18,RollupData!$A$2:$A$656,0)),"") -> 6:00p ASAP | O16: =IFERROR(INDEX(RollupData!$B$2:$B$656,MATCH($B16&"|"&TEXT($C$5,"yyyymmdd")&"|"&19,RollupData!$A$2:$A$656,0)),"") | P16: =IFERROR(INDEX(RollupData!$B$2:$B$656,MATCH($B16&"|"&TEXT($C$5,"yyyymmdd")&"|"&20,RollupData!$A$2:$A$656,0)),"") | Q16: =IFERROR(INDEX(RollupData!$B$2:$B$656,MATCH($B16&"|"&TEXT($C$5,"yyyymmdd")&"|"&21,RollupData!$A$2:$A$656,0)),"") | R16: =IFERROR(INDEX(RollupData!$D$2:$D$656,MATCH($B16&"|"&TEXT($C$5,"yyyymmdd"),RollupData!$C$2:$C$656,0)),"")
B17: ARC | C17: =COUNTIFS(Consolidated!$B$5:$B$659,$B17,Consolidated!$C$5:$C$659,$C$5) -> 2 | D17: =IFERROR(INDEX(RollupData!$B$2:$B$656,MATCH($B17&"|"&TEXT($C$5,"yyyymmdd")&"|"&8,RollupData!$A$2:$A$656,0)),"") | E17: =IFERROR(INDEX(RollupData!$B$2:$B$656,MATCH($B17&"|"&TEXT($C$5,"yyyymmdd")&"|"&9,RollupData!$A$2:$A$656,0)),"") | F17: =IFERROR(INDEX(RollupData!$B$2:$B$656,MATCH($B17&"|"&TEXT($C$5,"yyyymmdd")&"|"&10,RollupData!$A$2:$A$656,0)),"") -> 10:30a NCs | G17: =IFERROR(INDEX(RollupData!$B$2:$B$656,MATCH($B17&"|"&TEXT($C$5,"yyyymmdd")&"|"&11,RollupData!$A$2:$A$656,0)),"") | H17: =IFERROR(INDEX(RollupData!$B$2:$B$656,MATCH($B17&"|"&TEXT($C$5,"yyyymmdd")&"|"&12,RollupData!$A$2:$A$656,0)),"") | I17: =IFERROR(INDEX(RollupData!$B$2:$B$656,MATCH($B17&"|"&TEXT($C$5,"yyyymmdd")&"|"&13,RollupData!$A$2:$A$656,0)),"") | J17: =IFERROR(INDEX(RollupData!$B$2:$B$656,MATCH($B17&"|"&TEXT($C$5,"yyyymmdd")&"|"&14,RollupData!$A$2:$A$656,0)),"") | K17: =IFERROR(INDEX(RollupData!$B$2:$B$656,MATCH($B17&"|"&TEXT($C$5,"yyyymmdd")&"|"&15,RollupData!$A$2:$A$656,0)),"") -> 3:30p All | L17: =IFERROR(INDEX(RollupData!$B$2:$B$656,MATCH($B17&"|"&TEXT($C$5,"yyyymmdd")&"|"&16,RollupData!$A$2:$A$656,0)),"") | M17: =IFERROR(INDEX(RollupData!$B$2:$B$656,MATCH($B17&"|"&TEXT($C$5,"yyyymmdd")&"|"&17,RollupData!$A$2:$A$656,0)),"") | N17: =IFERROR(INDEX(RollupData!$B$2:$B$656,MATCH($B17&"|"&TEXT($C$5,"yyyymmdd")&"|"&18,RollupData!$A$2:$A$656,0)),"") | O17: =IFERROR(INDEX(RollupData!$B$2:$B$656,MATCH($B17&"|"&TEXT($C$5,"yyyymmdd")&"|"&19,RollupData!$A$2:$A$656,0)),"") | P17: =IFERROR(INDEX(RollupData!$B$2:$B$656,MATCH($B17&"|"&TEXT($C$5,"yyyymmdd")&"|"&20,RollupData!$A$2:$A$656,0)),"") | Q17: =IFERROR(INDEX(RollupData!$B$2:$B$656,MATCH($B17&"|"&TEXT($C$5,"yyyymmdd")&"|"&21,RollupData!$A$2:$A$656,0)),"") | R17: =IFERROR(INDEX(RollupData!$D$2:$D$656,MATCH($B17&"|"&TEXT($C$5,"yyyymmdd"),RollupData!$C$2:$C$656,0)),"") -> Broken Promise / Recent Pay / Dialer Only
B18: Optional Products | C18: =COUNTIFS(Consolidated!$B$5:$B$659,$B18,Consolidated!$C$5:$C$659,$C$5) -> 1 | D18: =IFERROR(INDEX(RollupData!$B$2:$B$656,MATCH($B18&"|"&TEXT($C$5,"yyyymmdd")&"|"&8,RollupData!$A$2:$A$656,0)),"") | E18: =IFERROR(INDEX(RollupData!$B$2:$B$656,MATCH($B18&"|"&TEXT($C$5,"yyyymmdd")&"|"&9,RollupData!$A$2:$A$656,0)),"") | F18: =IFERROR(INDEX(RollupData!$B$2:$B$656,MATCH($B18&"|"&TEXT($C$5,"yyyymmdd")&"|"&10,RollupData!$A$2:$A$656,0)),"") | G18: =IFERROR(INDEX(RollupData!$B$2:$B$656,MATCH($B18&"|"&TEXT($C$5,"yyyymmdd")&"|"&11,RollupData!$A$2:$A$656,0)),"") | H18: =IFERROR(INDEX(RollupData!$B$2:$B$656,MATCH($B18&"|"&TEXT($C$5,"yyyymmdd")&"|"&12,RollupData!$A$2:$A$656,0)),"") | I18: =IFERROR(INDEX(RollupData!$B$2:$B$656,MATCH($B18&"|"&TEXT($C$5,"yyyymmdd")&"|"&13,RollupData!$A$2:$A$656,0)),"") | J18: =IFERROR(INDEX(RollupData!$B$2:$B$656,MATCH($B18&"|"&TEXT($C$5,"yyyymmdd")&"|"&14,RollupData!$A$2:$A$656,0)),"") | K18: =IFERROR(INDEX(RollupData!$B$2:$B$656,MATCH($B18&"|"&TEXT($C$5,"yyyymmdd")&"|"&15,RollupData!$A$2:$A$656,0)),"") | L18: =IFERROR(INDEX(RollupData!$B$2:$B$656,MATCH($B18&"|"&TEXT($C$5,"yyyymmdd")&"|"&16,RollupData!$A$2:$A$656,0)),"") | M18: =IFERROR(INDEX(RollupData!$B$2:$B$656,MATCH($B18&"|"&TEXT($C$5,"yyyymmdd")&"|"&17,RollupData!$A$2:$A$656,0)),"") | N18: =IFERROR(INDEX(RollupData!$B$2:$B$656,MATCH($B18&"|"&TEXT($C$5,"yyyymmdd")&"|"&18,RollupData!$A$2:$A$656,0)),"") | O18: =IFERROR(INDEX(RollupData!$B$2:$B$656,MATCH($B18&"|"&TEXT($C$5,"yyyymmdd")&"|"&19,RollupData!$A$2:$A$656,0)),"") | P18: =IFERROR(INDEX(RollupData!$B$2:$B$656,MATCH($B18&"|"&TEXT($C$5,"yyyymmdd")&"|"&20,RollupData!$A$2:$A$656,0)),"") | Q18: =IFERROR(INDEX(RollupData!$B$2:$B$656,MATCH($B18&"|"&TEXT($C$5,"yyyymmdd")&"|"&21,RollupData!$A$2:$A$656,0)),"") | R18: =IFERROR(INDEX(RollupData!$D$2:$D$656,MATCH($B18&"|"&TEXT($C$5,"yyyymmdd"),RollupData!$C$2:$C$656,0)),"") -> Priority Order: Second/Third
B19: Call Escalation Team | C19: =COUNTIFS(Consolidated!$B$5:$B$659,$B19,Consolidated!$C$5:$C$659,$C$5) -> 0 | D19: =IFERROR(INDEX(RollupData!$B$2:$B$656,MATCH($B19&"|"&TEXT($C$5,"yyyymmdd")&"|"&8,RollupData!$A$2:$A$656,0)),"") | E19: =IFERROR(INDEX(RollupData!$B$2:$B$656,MATCH($B19&"|"&TEXT($C$5,"yyyymmdd")&"|"&9,RollupData!$A$2:$A$656,0)),"") | F19: =IFERROR(INDEX(RollupData!$B$2:$B$656,MATCH($B19&"|"&TEXT($C$5,"yyyymmdd")&"|"&10,RollupData!$A$2:$A$656,0)),"") | G19: =IFERROR(INDEX(RollupData!$B$2:$B$656,MATCH($B19&"|"&TEXT($C$5,"yyyymmdd")&"|"&11,RollupData!$A$2:$A$656,0)),"") | H19: =IFERROR(INDEX(RollupData!$B$2:$B$656,MATCH($B19&"|"&TEXT($C$5,"yyyymmdd")&"|"&12,RollupData!$A$2:$A$656,0)),"") | I19: =IFERROR(INDEX(RollupData!$B$2:$B$656,MATCH($B19&"|"&TEXT($C$5,"yyyymmdd")&"|"&13,RollupData!$A$2:$A$656,0)),"") | J19: =IFERROR(INDEX(RollupData!$B$2:$B$656,MATCH($B19&"|"&TEXT($C$5,"yyyymmdd")&"|"&14,RollupData!$A$2:$A$656,0)),"") | K19: =IFERROR(INDEX(RollupData!$B$2:$B$656,MATCH($B19&"|"&TEXT($C$5,"yyyymmdd")&"|"&15,RollupData!$A$2:$A$656,0)),"") | L19: =IFERROR(INDEX(RollupData!$B$2:$B$656,MATCH($B19&"|"&TEXT($C$5,"yyyymmdd")&"|"&16,RollupData!$A$2:$A$656,0)),"") | M19: =IFERROR(INDEX(RollupData!$B$2:$B$656,MATCH($B19&"|"&TEXT($C$5,"yyyymmdd")&"|"&17,RollupData!$A$2:$A$656,0)),"") | N19: =IFERROR(INDEX(RollupData!$B$2:$B$656,MATCH($B19&"|"&TEXT($C$5,"yyyymmdd")&"|"&18,RollupData!$A$2:$A$656,0)),"") | O19: =IFERROR(INDEX(RollupData!$B$2:$B$656,MATCH($B19&"|"&TEXT($C$5,"yyyymmdd")&"|"&19,RollupData!$A$2:$A$656,0)),"") | P19: =IFERROR(INDEX(RollupData!$B$2:$B$656,MATCH($B19&"|"&TEXT($C$5,"yyyymmdd")&"|"&20,RollupData!$A$2:$A$656,0)),"") | Q19: =IFERROR(INDEX(RollupData!$B$2:$B$656,MATCH($B19&"|"&TEXT($C$5,"yyyymmdd")&"|"&21,RollupData!$A$2:$A$656,0)),"") | R19: =IFERROR(INDEX(RollupData!$D$2:$D$656,MATCH($B19&"|"&TEXT($C$5,"yyyymmdd"),RollupData!$C$2:$C$656,0)),"")
B21: Legend: | D21: AMs (auto-msg) | F21: Branch | H21: WFO | J21: Blitz | L21: TSC | N21: Vendor
B23: CD TEAM COVERAGE (fill from the Assignments workbook) | J23: HOURS OF OPERATION
B24: Area | C24: AM | D24: Mid-Day | E24: PM | J24: Area | K24: Groups | L24: Open | M24: Close
B25: Central Collections | J25: Card Collections | K25: 40 / 80 | L25: =IFERROR(INDEX('Ref Card Hours'!$B$2:$B$40,MATCH('Daily Rollup'!$C$5,'Ref Card Hours'!$A$2:$A$40,0)),"") -> 8:00am | M25: =IFERROR(INDEX('Ref Card Hours'!$C$2:$C$40,MATCH('Daily Rollup'!$C$5,'Ref Card Hours'!$A$2:$A$40,0)),"") -> 8:00pm
B26: Inbound (Sales / Care) | J26: Call Escalation Team | K26: 37 / 77 | L26: 8:00 AM | M26: 5:00 PM
B27: Card | J27: Optional Products | K27: 130 / 131 | L27: 8:00 AM | M27: 6:00 PM
B28: Escalations / NICE
B30: This page rebuilds itself from the Consolidated tab — refresh the import, pick a date, and it's ready to send. No cross-sheet formula web, nothing to break.

Sheet START HERE
B2: CALL DELIVERY — MASTER WORKBOOK
B3: One refresh pulls every business group's schedule out of the shared Intake folder.
B5: DAILY USE (after one-time setup)
B6: 1. Open this workbook.
B7: 2. Data → Refresh All.
B8: 3. Done — the Consolidated tab now holds every group's current schedule.
B10: ONE-TIME SETUP (about 5 minutes)
B11: 1. Give each group its own folder under the shared Intake root; files are named by month:
B12: \\CallDelivery\Intake\FE\2026-08.xlsx \Intake\Card\2026-08.xlsx ...
B13: Grant each group write access to THEIR folder only - nobody can touch another group's schedule.
B14: 2. On the Settings tab set the Intake root (C3) and the month to load (C4 - the IntakeMonth named range).
B15: 3. Data → Get Data → Launch Power Query Editor → New Source → Blank Query.
... B31: never break another group or the rollup.

Sheet Settings
B2: Setting | C2: Value
B3: Intake root (IntakeRoot in the query) | C3: \\CallDelivery\Intake | E3: New month = change C4 + Refresh All. The query reads C4 through the IntakeMonth named range and loads every group folder's matching file.
B4: Month to load (IntakeMonth) | C4: 2026-07

Sheet Consolidated
B2: CONSOLIDATED SCHEDULE — sample pre-load (this becomes the Power Query output)
B4: Business Group | C4: Date | D4: Start Time (ET) | E4: Timezone Wave | F4: List ID / Campaign | G4: Priority | H4: Segment / Tag | I4: Special Instructions | J4: Source File
B5: ARC | C5: 46204 | D5: 0.47916667 | F5: N/A | G5: 1 | H5: NCs | I5: Preplacement / Strat 2 | J5: ARC\2026-07.xlsx
B6: ARC | C6: 46204 | D6: 0.64583333 | E6: All | F6: N/A | G6: 2 | I6: Preplacement / Strat 2 | J6: ARC\2026-07.xlsx
B7: Auto | C7: 46204 | D7: 0.35416667 | E7: E | F7: N/A | G7: 1 | H7: AMs | I7: Slowpay AM Daily | J7: Auto\2026-07.xlsx
B8: Auto | C8: 46204 | D8: 0.47916667 | E8: C-M-P | F8: N/A | G8: 2 | H8: AMs | J8: Auto\2026-07.xlsx
B9: Auto | C9: 46204 | D9: 0.58333333 | F9: N/A | G9: 3 | H9: WFO | J9: Auto\2026-07.xlsx
B10: Auto | C10: 46204 | D10: 0.70833333 | F10: N/A | G10: 4 | H10: Blitz | J10: Auto\2026-07.xlsx
B11: Auto | C11: 46204 | D11: 0.83333333 | F11: N/A | G11: 5 | H11: TSC (All) | J11: Auto\2026-07.xlsx
B12: BE | C12: 46204 | D12: 0.41666667 | E12: E-C-M | F12: N/A | G12: 1 | H12: AMs | J12: BE\2026-07.xlsx
B13: BE | C13: 46204 | D13: 0.47916667 | E13: P | F13: N/A | G13: 2 | H13: AMs | J13: BE\2026-07.xlsx
B14: BE | C14: 46204 | D14: 0.58333333 | F14: N/A | G14: 3 | H14: WFO | J14: BE\2026-07.xlsx
B15: BE | C15: 46204 | D15: 0.66666667 | E15: All | F15: N/A | G15: 4 | J15: BE\2026-07.xlsx
B16: BE | C16: 46204 | D16: 0.75 | E16: All | F16: N/A | G16: 5 | J16: BE\2026-07.xlsx
B17: BE | C17: 46204 | D17: 0.83333333 | F17: N/A | G17: 6 | H17: TSC (All) | J17: BE\2026-07.xlsx
B18: Branch Central | C18: 46204 | D18: 0.52083333 | E18: E-C | F18: N/A | G18: 1 | H18: 1s & Slow | J18: Branch_Central\2026-07.xlsx
B19: Card | C19: 46204 | D19: 0.33333333 | F19: N/A | G19: 1 | J19: Card\2026-07.xlsx
B20: Card | C20: 46204 | D20: 0.5 | F20: N/A | G20: 2 | J20: Card\2026-07.xlsx
B21: Card | C21: 46204 | D21: 0.58333333 | F21: N/A | G21: 3 | H21: ASAP | J21: Card\2026-07.xlsx
B22: Card | C22: 46204 | D22: 0.66666667 | F22: N/A | G22: 4 | H22: ASAP | J22: Card\2026-07.xlsx
B23: Card | C23: 46204 | D23: 0.75 | F23: N/A | G23: 5 | H23: ASAP | J23: Card\2026-07.xlsx
B24: FE | C24: 46204 | D24: 0.34375 | E24: E | F24: N/A | G24: 1 | H24: AMs | J24: FE\2026-07.xlsx
B25: FE | C25: 46204 | D25: 0.38541667 | E25: C | F25: N/A | G25: 2 | H25: AMs | J25: FE\2026-07.xlsx
B26: FE | C26: 46204 | D26: 0.47916667 | E26: M-P | F26: N/A | G26: 3 | H26: AMs | J26: FE\2026-07.xlsx
B27: FE | C27: 46204 | D27: 0.52083333 | F27: N/A | G27: 4 | H27: Branch | J27: FE\2026-07.xlsx
B28: FE | C28: 46204 | D28: 0.60416667 | F28: N/A | G28: 5 | H28: WFO | J28: FE\2026-07.xlsx
B29: FE | C29: 46204 | D29: 0.70833333 | F29: N/A | G29: 6 | H29: Blitz | J29: FE\2026-07.xlsx
B30: FE | C30: 46204 | D30: 0.83333333 | F30: N/A | G30: 7 | H30: TSC (All) | J30: FE\2026-07.xlsx
B31: Optional Products | C31: 46204 | F31: N/A | G31: 1 | H31: Second | I31: Priority Order: Second | J31: Optional_Products\2026-07.xlsx
B32: Repo | C32: 46204 | D32: 0.41666667 | F32: N/A | G32: 1 | H32: RP | I32: AM Daily | J32: Repo\2026-07.xlsx
B33: Repo | C33: 46204 | D33: 0.5 | F33: N/A | G33: 2 | H33: RP | J33: Repo\2026-07.xlsx
B34: Repo | C34: 46204 | D34: 0.54166667 | F34: N/A | G34: 3 | H34: Repo | J34: Repo\2026-07.xlsx
B35: Repo | C35: 46204 | D35: 0.625 | F35: N/A | G35: 4 | H35: Repo | J35: Repo\2026-07.xlsx
B36: ARC | C36: 46205 | D36: 0.58333333 | F36: N/A | G36: 1 | H36: NCs | I36: Broken Promise / Recent Pay / Dialer Only | J36: ARC\2026-07.xlsx
B37: Auto | C37: 46205 | D37: 0.34375 | E37: E | F37: N/A | G37: 1 | I37: Slowpay AM Daily | J37: Auto\2026-07.xlsx
B38: Auto | C38: 46205 | D38: 0.47916667 | E38: C-M-P | F38: N/A | G38: 2 | J38: Auto\2026-07.xlsx
B39: Auto | C39: 46205 | D39: 0.54166667 | F39: N/A | G39: 3 | H39: WFO | J39: Auto\2026-07.xlsx
B40: Auto | C40: 46205 | D40: 0.70833333 | F40: N/A | G40: 4 | H40: Blitz | J40: Auto\2026-07.xlsx
B41: Auto | C41: 46205 | D41: 0.83333333 | F41: N/A | G41: 5 | H41: TSC (All) | J41: Auto\2026-07.xlsx
B42: BE | C42: 46205 | D42: 0.35416667 | E42: E | F42: N/A | G42: 1 | J42: BE\2026-07.xlsx
...

Sheet Ref Voice
A1: AUTO-MESSAGING VOICE — daily calendar (Daily Rollup reads this)
A2: Date | B2: Voice
A3: 46204 | B3: Female
A4: 46205 | B4: N/A
A5: 46206 | B5: Female
A6: 46207
A7: 46208
A8: 46209 | B8: Male
A9: 46210 | B9: N/A
A10: 46211 | B10: Male
A11: 46212 | B11: N/A
A12: 46213 | B12: Male
A13: 46214
A14: 46215
A15: 46216 | B15: Female
A16: 46217 | B16: N/A
A17: 46218 | B17: Female
A18: 46219 | B18: N/A
A19: 46220 | B19: Female
A20: 46221
A21: 46222
A22: 46223 | B22: Male
A23: 46224 | B23: N/A
A24: 46225 | B24: Male
A25: 46226 | B25: N/A
A26: 46227 | B26: Male
A27: 46228
A28: 46229
A29: 46230 | B29: Female
A30: 46231 | B30: N/A
A31: 46232 | B31: Female
A32: 46233 | B32: N/A
A33: 46234 | B33: Female

Sheet Ref AM Voice IDs
A1: AUTO-MESSAGE CAMPAIGN & VOICE IDs
A2: Campaign | B2: Lists | C2: Female ID | D2: Male ID
A3: APP/AUTO | B3: ADAN,ADAO,ADAR | C3: 297 | D3: 304
A4: FE | B4: FEAO,FEAR | C4: 299 | D4: 307
A5: BE | B5: BEAO,BEAR | C5: 298 | D5: 305
A6: PCO | B6: PCAO,PCAR | C6: 300 | D6: 308
A7: REPO (PRC & RP) | B7: REAO, REAH | C7: 301 | D7: 309
A8: CARD | B8: BWAO, BWAR | C8: 296 | D8: 306
A9: SALES NCC/APPS | B9: NCAO, NCAH | C9: 302 | D9: 311
A10: SALES AH | B10: LDA3, LDA4 | C10: 315 | D10: 314
A11: UNC APPS/PC LEADS | B11: SAMO, SAMR | C11: 312 | D11: 313

Sheet Ref Card Hours
A1: CARD HOURS — daily open/close (Daily Rollup reads this)
A2: Date | B2: Open | C2: Close | D2: Week
A3: 46204 | B3: 8:00am | C3: 10:00pm | D3: Week 1
A4: 46205 | B4: 8:00am | C4: 10:00pm | D4: Week 1
A5: 46206 | B5: 8:00am | C5: 8:00pm | D5: Week 1
A6: 46207 | B6: 9:00am | C6: 8:00pm | D6: Week 1
A7: 46208 | D7: 0
A8: 46209 | B8: 8:00am | C8: 10:00pm | D8: Week 2
A9: 46210 | B9: 8:00am | C9: 10:00pm | D9: Week 2
A10: 46211 | B10: 8:00am | C10: 10:00pm | D10: Week 2
A11: 46212 | B11: 8:00am | C11: 10:00pm | D11: Week 2
A12: 46213 | B12: 8:00am | C12: 8:00pm | D12: Week 2
A13: 46214 | B13: 9:00am | C13: 8:00pm | D13: Week 2
A14: 46215 | D14: 0
A15: 46216 | B15: 8:00am | C15: 10:00pm | D15: Week 1
A16: 46217 | B16: 8:00am | C16: 10:00pm | D16: Week 1
A17: 46218 | B17: 8:00am | C17: 10:00pm | D17: Week 1
A18: 46219 | B18: 8:00am | C18: 10:00pm | D18: Week 1
A19: 46220 | B19: 8:00am | C19: 8:00pm | D19: Week 1
A20: 46221 | B20: 9:00am | C20: 8:00pm | D20: Week 1
A21: 46222 | D21: 0
A22: 46223 | B22: 8:00am | C22: 10:00pm | D22: Week 2
A23: 46224 | B23: 8:00am | C23: 10:00pm | D23: Week 2
A24: 46225 | B24: 7:00a | C24: 10:00pm | D24: Week 2
A25: 46226 | B25: 8:00am | C25: 10:00pm | D25: Week 2
A26: 46227 | B26: 8:00am | C26: 8:00pm | D26: Week 2
A27: 46228 | B27: 9:00am | C27: 8:00pm | D27: Week 2
A28: 46229 | D28: 0
A29: 46230 | B29: 8:00am | C29: 10:00pm | D29: Week 1
A30: 46231 | B30: 8:00am | C30: 10:00pm | D30: Week 1
A31: 46232 | B31: 8:00am | C31: 10:00pm | D31: Week 1
A32: 46233 | B32: 8:00am | C32: 10:00pm | D32: Week 1
A33: 46234 | B33: 8:00am | C33: 8:00pm | D33: Week 1

Sheet Ref Branch Strategy
A1: BRANCH STANDING STRATEGY — weekly list priorities (1Pay & 2Pay)
A3: 1PAY BRANCH STRATEGY
A4: Monday | B4: Mid-Day (11:30am CST) | F4: Vendor After Hours (5pm CST)
B5: LIST ID | C5: Priority | D5: TZ | E5: Desc | F5: LIST ID | G5: Priority | H5: Time Zone
B6: BR_CAP_CONS_LB | C6: 1 | D6: E-C | E6: 1Pay Capacity Constrained below $7500 | F6: BR_CAP_CONS_LB | G6: 1 | H6: M-P | I6: 1Pay Capacity Constrained below $7500
B7: BR_CAP_CONS_SLOW_LB | C7: 2 | D7: E-C | E7: Slow Pay Capacity Constrained below $7500 | F7: BR_ADHOC_HB | G7: 2 | H7: All | I7: Branch requested support
B8: BR_CAP_CONS_SLOW_HB | C8: 3 | D8: E-C | E8: Slow Pay Capacity Constrained above $7500 | F8: BR_ADHOC_LB | G8: 3 | H8: All | I8: Branch requested support
F9: BR_CAP_CONS_HB | G9: 4 | H9: All | I9: 1Pay Capacity Constrained above $7500
F10: BR_CAP_CONS_LB | G10: 5 | H10: All | I10: 1Pay Capacity Constrained below $7500
F11: BR_1PAY_HB | G11: 6 | H11: All | I11: 1Pay above $7500 outside of cap constrained (remaining branches)
F12: BR_1PAY_LB | G12: 7 | H12: All | I12: 1Pay below $7500 outside of cap constrained (remaining branches)
F13: BR_CAP_CONS_SLOW_HB | G13: 8 | H13: All | I13: Slow Pay Capacity Constrained above $7500
F14: BR_CAP_CONS_SLOW_LB | G14: 9 | H14: All | I14: Slow Pay Capacity Constrained below $7500
F15: BR_SLOW_HB | G15: 10 | H15: All | I15: Slow Pay above $7500 outside of cap constrained (remaining branches)
F16: BR_SLOW_LB | G16: 11 | H16: All | I16: Slow Pay below $7500 outside of cap constrained (remaining branches)
A17: Tuesday | B17: Mid-Day (11:30am CST) | F17: Vendor After Hours (5pm CST)
B18: LIST ID | C18: Priority | D18: TZ | E18: Desc | F18: LIST ID | G18: Priority | H18: Time Zone
B19: BR_CAP_CONS_LB | C19: 1 | D19: E-C | E19: 1Pay Capacity Constrained below $7500 | F19: BR_CAP_CONS_LB | G19: 1 | H19: M-P | I19: 1Pay Capacity Constrained below $7500
B20: BR_CAP_CONS_SLOW_LB | C20: 2 | D20: E-C | E20: Slow Pay Capacity Constrained below $7500 | F20: BR_ADHOC_HB | G20: 2 | H20: All | I20: Branch requested support
B21: BR_CAP_CONS_SLOW_HB | C21: 3 | D21: E-C | E21: Slow Pay Capacity Constrained above $7500 | F21: BR_ADHOC_LB | G21: 3 | H21: All | I21: Branch requested support
F22: BR_CAP_CONS_HB | G22: 4 | H22: All | I22: 1Pay Capacity Constrained above $7500
F23: BR_CAP_CONS_LB | G23: 5 | H23: All | I23: 1Pay Capacity Constrained below $7500
F24: BR_1PAY_HB | G24: 6 | H24: All | I24: 1Pay above $7500 outside of cap constrained (remaining branches)
F25: BR_1PAY_LB | G25: 7 | H25: All | I25: 1Pay below $7500 outside of cap constrained (remaining branches)
F26: BR_CAP_CONS_SLOW_HB | G26: 8 | H26: All | I26: Slow Pay Capacity Constrained above $7500
F27: BR_CAP_CONS_SLOW_LB | G27: 9 | H27: All | I27: Slow Pay Capacity Constrained below $7500
F28: BR_SLOW_HB | G28: 10 | H28: All | I28: Slow Pay above $7500 outside of cap constrained (remaining branches)
F29: BR_SLOW_LB | G29: 11 | H29: All | I29: Slow Pay below $7500 outside of cap constrained (remaining branches)
A30: Wednesday | B30: Mid-Day (11:30am CST) | F30: Vendor After Hours (5pm CST)
B31: LIST ID | C31: Priority | D31: TZ | E31: Desc | F31: LIST ID | G31: Priority | H31: Time Zone
B32: BR_CAP_CONS_LB | C32: 1 | D32: E-C | E32: 1Pay Capacity Constrained below $7500 | F32: BR_CAP_CONS_LB | G32: 1 | H32: M-P | I32: 1Pay Capacity Constrained below $7500
B33: BR_CAP_CONS_SLOW_LB | C33: 2 | D33: E-C | E33: Slow Pay Capacity Constrained below $7500 | F33: BR_ADHOC_HB | G33: 2 | H33: All | I33: Branch requested support
B34: BR_CAP_CONS_SLOW_HB | C34: 3 | D34: E-C | E34: Slow Pay Capacity Constrained above $7500 | F34: BR_ADHOC_LB | G34: 3 | H34: All | I34: Branch requested support
F35: BR_CAP_CONS_HB | G35: 4 | H35: All | I35: 1Pay Capacity Constrained above $7500
F36: BR_CAP_CONS_LB | G36: 5 | H36: All | I36: 1Pay Capacity Constrained below $7500
F37: BR_1PAY_HB | G37: 6 | H37: All | I37: 1Pay above $7500 outside of cap constrained (remaining branches)
F38: BR_1PAY_LB | G38: 7 | H38: All | I38: 1Pay below $7500 outside of cap constrained (remaining branches)
F39: BR_CAP_CONS_SLOW_HB | G39: 8 | H39: All | I39: Slow Pay Capacity Constrained above $7500
F40: BR_CAP_CONS_SLOW_LB | G40: 9 | H40: All | I40: Slow Pay Capacity Constrained below $7500
F41: BR_SLOW_HB | G41: 10 | H41: All | I41: Slow Pay above $7500 outside of cap constrained (remaining branches)
...

Sheet Ref Blitz Rules
A1: BLITZ STANDING RULES — windows, recall time, designated lists
A3: 30 min recall time after ALL 1st attempts
A4: FE | B4: Groups 14 / 54 | F4: BE | G4: Groups 12 / 52
B5: M-F Evening | C5: 5p - 7p EST | G5: M-F Evening | H5: 5p - 7p EST
C6: Lists | H6: Lists
C7: All Central Population of Slows - 1Pay | H7: All Central Population of 3Pay - PCO
C8: Adhoc | H8: AdHoc
C9: All Auto Direct
C10: (All Branch accounts are called by Vendor)
B11: Designated 2Pay | C11: 4p - 6p EST | G11: Saturday AM | H11: 10a - 12p
C12: Lists | H12: Lists
C13: All Central Population of 2Pay | H13: All Central Population of 3Pay - PCO
C14: All Auto Direct FE | H14: AdHoc
C15: (All Central Slow & 1Pay dialed in passes outside of Blitz)
C16: (All Branch accounts are called by Vendor)
A18: Per-date blitz calendars live in each group's intake file (FE/BE notes panel).

Sheet RollupData
A1: key grp|date|hour | B1: display | C1: key grp|date | D1: note
A2: =IF(Consolidated!B5="","",Consolidated!B5&"|"&TEXT(Consolidated!C5,"yyyymmdd")&"|"&HOUR(Consolidated!D5)) -> ARC|20260701|11 | B2: =IF(Consolidated!B5="","",SUBSTITUTE(SUBSTITUTE(TEXT(Consolidated!D5,"h:mm AM/PM")," AM","a")," PM","p")&IF(Consolidated!E5="",""," "&Consolidated!E5)&IF(Consolidated!H5="",""," "&Consolidated!H5)) -> 11:30a NCs | C2: =IF(Consolidated!B5="","",Consolidated!B5&"|"&TEXT(Consolidated!C5,"yyyymmdd")) -> ARC|20260701 | D2: =IF(Consolidated!I5="","",Consolidated!I5) -> Preplacement / Strat 2
A3: =IF(Consolidated!B6="","",Consolidated!B6&"|"&TEXT(Consolidated!C6,"yyyymmdd")&"|"&HOUR(Consolidated!D6)) -> ARC|20260701|15 | B3: =IF(Consolidated!B6="","",SUBSTITUTE(SUBSTITUTE(TEXT(Consolidated!D6,"h:mm AM/PM")," AM","a")," PM","p")&IF(Consolidated!E6="",""," "&Consolidated!E6)&IF(Consolidated!H6="",""," "&Consolidated!H6)) -> 3:30p All | C3: =IF(Consolidated!B6="","",Consolidated!B6&"|"&TEXT(Consolidated!C6,"yyyymmdd")) -> ARC|20260701 | D3: =IF(Consolidated!I6="","",Consolidated!I6) -> Preplacement / Strat 2
A4: =IF(Consolidated!B7="","",Consolidated!B7&"|"&TEXT(Consolidated!C7,"yyyymmdd")&"|"&HOUR(Consolidated!D7)) -> Auto|20260701|8 | B4: =IF(Consolidated!B7="","",SUBSTITUTE(SUBSTITUTE(TEXT(Consolidated!D7,"h:mm AM/PM")," AM","a")," PM","p")&IF(Consolidated!E7="",""," "&Consolidated!E7)&IF(Consolidated!H7="",""," "&Consolidated!H7)) -> 8:30a E AMs | C4: =IF(Consolidated!B7="","",Consolidated!B7&"|"&TEXT(Consolidated!C7,"yyyymmdd")) -> Auto|20260701 | D4: =IF(Consolidated!I7="","",Consolidated!I7) -> Slowpay AM Daily
A5: =IF(Consolidated!B8="","",Consolidated!B8&"|"&TEXT(Consolidated!C8,"yyyymmdd")&"|"&HOUR(Consolidated!D8)) -> Auto|20260701|11 | B5: =IF(Consolidated!B8="","",SUBSTITUTE(SUBSTITUTE(TEXT(Consolidated!D8,"h:mm AM/PM")," AM","a")," PM","p")&IF(Consolidated!E8="",""," "&Consolidated!E8)&IF(Consolidated!H8="",""," "&Consolidated!H8)) -> 11:30a C-M-P AMs | C5: =IF(Consolidated!B8="","",Consolidated!B8&"|"&TEXT(Consolidated!C8,"yyyymmdd")) -> Auto|20260701 | D5: =IF(Consolidated!I8="","",Consolidated!I8)
A6: =IF(Consolidated!B9="","",Consolidated!B9&"|"&TEXT(Consolidated!C9,"yyyymmdd")&"|"&HOUR(Consolidated!D9)) -> Auto|20260701|14 | B6: =IF(Consolidated!B9="","",SUBSTITUTE(SUBSTITUTE(TEXT(Consolidated!D9,"h:mm AM/PM")," AM","a")," PM","p")&IF(Consolidated!E9="",""," "&Consolidated!E9)&IF(Consolidated!H9="",""," "&Consolidated!H9)) -> 2:00p WFO | C6: =IF(Consolidated!B9="","",Consolidated!B9&"|"&TEXT(Consolidated!C9,"yyyymmdd")) -> Auto|20260701 | D6: =IF(Consolidated!I9="","",Consolidated!I9)
A7: =IF(Consolidated!B10="","",Consolidated!B10&"|"&TEXT(Consolidated!C10,"yyyymmdd")&"|"&HOUR(Consolidated!D10)) -> Auto|20260701|17 | B7: =IF(Consolidated!B10="","",SUBSTITUTE(SUBSTITUTE(TEXT(Consolidated!D10,"h:mm AM/PM")," AM","a")," PM","p")&IF(Consolidated!E10="",""," "&Consolidated!E10)&IF(Consolidated!H10="",""," "&Consolidated!H10)) -> 5:00p Blitz | C7: =IF(Consolidated!B10="","",Consolidated!B10&"|"&TEXT(Consolidated!C10,"yyyymmdd")) -> Auto|20260701 | D7: =IF(Consolidated!I10="","",Consolidated!I10)
A8: =IF(Consolidated!B11="","",Consolidated!B11&"|"&TEXT(Consolidated!C11,"yyyymmdd")&"|"&HOUR(Consolidated!D11)) -> Auto|20260701|20 | B8: =IF(Consolidated!B11="","",SUBSTITUTE(SUBSTITUTE(TEXT(Consolidated!D11,"h:mm AM/PM")," AM","a")," PM","p")&IF(Consolidated!E11="",""," "&Consolidated!E11)&IF(Consolidated!H11="",""," "&Consolidated!H11)) -> 8:00p TSC (All) | C8: =IF(Consolidated!B11="","",Consolidated!B11&"|"&TEXT(Consolidated!C11,"yyyymmdd")) -> Auto|20260701 | D8: =IF(Consolidated!I11="","",Consolidated!I11)
A9: =IF(Consolidated!B12="","",Consolidated!B12&"|"&TEXT(Consolidated!C12,"yyyymmdd")&"|"&HOUR(Consolidated!D12)) -> BE|20260701|10 | B9: =IF(Consolidated!B12="","",SUBSTITUTE(SUBSTITUTE(TEXT(Consolidated!D12,"h:mm AM/PM")," AM","a")," PM","p")&IF(Consolidated!E12="",""," "&Consolidated!E12)&IF(Consolidated!H12="",""," "&Consolidated!H12)) -> 10:00a E-C-M AMs | C9: =IF(Consolidated!B12="","",Consolidated!B12&"|"&TEXT(Consolidated!C12,"yyyymmdd")) -> BE|20260701 | D9: =IF(Consolidated!I12="","",Consolidated!I12)
A10: =IF(Consolidated!B13="","",Consolidated!B13&"|"&TEXT(Consolidated!C13,"yyyymmdd")&"|"&HOUR(Consolidated!D13)) -> BE|20260701|11 | B10: =IF(Consolidated!B13="","",SUBSTITUTE(SUBSTITUTE(TEXT(Consolidated!D13,"h:mm AM/PM")," AM","a")," PM","p")&IF(Consolidated!E13="",""," "&Consolidated!E13)&IF(Consolidated!H13="",""," "&Consolidated!H13)) -> 11:30a P AMs | C10: =IF(Consolidated!B13="","",Consolidated!B13&"|"&TEXT(Consolidated!C13,"yyyymmdd")) -> BE|20260701 | D10: =IF(Consolidated!I13="","",Consolidated!I13)
A11: =IF(Consolidated!B14="","",Consolidated!B14&"|"&TEXT(Consolidated!C14,"yyyymmdd")&"|"&HOUR(Consolidated!D14)) -> BE|20260701|14 | B11: =IF(Consolidated!B14="","",SUBSTITUTE(SUBSTITUTE(TEXT(Consolidated!D14,"h:mm AM/PM")," AM","a")," PM","p")&IF(Consolidated!E14="",""," "&Consolidated!E14)&IF(Consolidated!H14="",""," "&Consolidated!H14)) -> 2:00p WFO | C11: =IF(Consolidated!B14="","",Consolidated!B14&"|"&TEXT(Consolidated!C14,"yyyymmdd")) -> BE|20260701 | D11: =IF(Consolidated!I14="","",Consolidated!I14)
A12: =IF(Consolidated!B15="","",Consolidated!B15&"|"&TEXT(Consolidated!C15,"yyyymmdd")&"|"&HOUR(Consolidated!D15)) -> BE|20260701|16 | B12: =IF(Consolidated!B15="","",SUBSTITUTE(SUBSTITUTE(TEXT(Consolidated!D15,"h:mm AM/PM")," AM","a")," PM","p")&IF(Consolidated!E15="",""," "&Consolidated!E15)&IF(Consolidated!H15="",""," "&Consolidated!H15)) -> 4:00p All | C12: =IF(Consolidated!B15="","",Consolidated!B15&"|"&TEXT(Consolidated!C15,"yyyymmdd")) -> BE|20260701 | D12: =IF(Consolidated!I15="","",Consolidated!I15)
A13: =IF(Consolidated!B16="","",Consolidated!B16&"|"&TEXT(Consolidated!C16,"yyyymmdd")&"|"&HOUR(Consolidated!D16)) -> BE|20260701|18 | B13: =IF(Consolidated!B16="","",SUBSTITUTE(SUBSTITUTE(TEXT(Consolidated!D16,"h:mm AM/PM")," AM","a")," PM","p")&IF(Consolidated!E16="",""," "&Consolidated!E16)&IF(Consolidated!H16="",""," "&Consolidated!H16)) -> 6:00p All | C13: =IF(Consolidated!B16="","",Consolidated!B16&"|"&TEXT(Consolidated!C16,"yyyymmdd")) -> BE|20260701 | D13: =IF(Consolidated!I16="","",Consolidated!I16)
... A656: =IF(Consolidated!B659="","",Consolidated!B659&"|"&TEXT(Consolidated!C659,"yyyymmdd")&"|"&HOUR(Consolidated!D659)) -> FE|20260725|10 | B656: =IF(Consolidated!B659="","",SUBSTITUTE(SUBSTITUTE(TEXT(Consolidated!D659,"h:mm AM/PM")," AM","a")," PM","p")&IF(Consolidated!E659="",""," "&Consolidated!E659)&IF(Consolidated!H659="",""," "&Consolidated!H659)) -> 10:00a Blitz | C656: =IF(Consolidated!B659="","",Consolidated!B659&"|"&TEXT(Consolidated!C659,"yyyymmdd")) -> FE|20260725 | D656: =IF(Consolidated!I659="","",Consolidated!I659)
